<?xml version="1.0" encoding="utf-8"?><test-results date="2019-10-19" name="SAFE Tests" total="1" errors="0" failures="1" ignored="0" not-run="0" inconclusive="0" skipped="0" invalid="0" time="09:59:44"><environment expecto-version="8.12.0" clr-version="3.1.0" os-version="Microsoft Windows NT 6.2.9200.0" platform="Linux" cwd="C:\Users\admini\Desktop\safe" machine-name="dev" user="admini" user-domain="dev" /><culture-info current-culture="en-US" current-uiculture="en-US" /><test-suite type="Assembly" name="SAFE Tests" executed="True" result="Failure" success="False" time="271.741" asserts="0"><results><test-case name="Project created from template/Project should build properly" executed="True" result="Failure" success="False" time="271.708" asserts="0"><failure><message>
Failed after 1 test. Parameters:
	{ Server = Some "giraffe"
  Deploy = None
  Layout = None
  JsDeps = None
  Communication = Some "remoting"
  Pattern = Some "streams" }
Shrunk 3 times to:
	{ Server = None
  Deploy = None
  Layout = None
  JsDeps = None
  Communication = None
  Pattern = None }
Result:
	Exception
  System.Exception: Process exit code '1' &lt;&gt; 0. Command Line: fake build
   at Fake.Core.CreateProcess.ensureExitCode@523.Invoke(a data, Int32 exitCode)
   at Fake.Core.CreateProcess.addOnExited@499-5.Invoke(RawProcessResult _arg2)
   at Microsoft.FSharp.Control.AsyncPrimitives.CallThenInvokeNoHijackCheck[a,b](AsyncActivation`1 ctxt, FSharpFunc`2 userCode, b result1) in E:\A\_work\130\s\src\fsharp\FSharp.Core\async.fs:line 417
   at Microsoft.FSharp.Control.Trampoline.Execute(FSharpFunc`2 firstAction) in E:\A\_work\130\s\src\fsharp\FSharp.Core\async.fs:line 109
--- End of stack trace from previous location where exception was thrown ---
   at Microsoft.FSharp.Control.AsyncResult`1.Commit() in E:\A\_work\130\s\src\fsharp\FSharp.Core\async.fs:line 350
   at Microsoft.FSharp.Control.AsyncPrimitives.RunSynchronouslyInCurrentThread[a](CancellationToken cancellationToken, FSharpAsync`1 computation) in E:\A\_work\130\s\src\fsharp\FSharp.Core\async.fs:line 882
   at Microsoft.FSharp.Control.AsyncPrimitives.RunSynchronously[T](CancellationToken cancellationToken, FSharpAsync`1 computation, FSharpOption`1 timeout) in E:\A\_work\130\s\src\fsharp\FSharp.Core\async.fs:line 890
   at Microsoft.FSharp.Control.FSharpAsync.RunSynchronously[T](FSharpAsync`1 computation, FSharpOption`1 timeout, FSharpOption`1 cancellationToken) in E:\A\_work\130\s\src\fsharp\FSharp.Core\async.fs:line 1154
   at Fake.Core.Proc.run[a](CreateProcess`1 c)
   at SAFE.Tests.run(String exe, String arg, String dir) in C:\Users\admini\Desktop\safe\tests\Tests.fs:line 166
   at SAFE.Tests.tests@262.Invoke(TemplateArgs x) in C:\Users\admini\Desktop\safe\tests\Tests.fs:line 274
   at FsCheck.Testable.evaluate[a,b](FSharpFunc`2 body, a a)
Focus on error:
	etestPropertyWithConfig (1614425584, 296659201) "Project should build properly"</message></failure></test-case></results></test-suite></test-results>